Workbook

Sheet AHSP 2026
A1: FORMULIR ANALISA HARGA SATUAN PEKERJAAN (AHSP) 2026
A3: Item | B3: Pemasangan 1 m' kabel NYY 4 x 16 mm² | E3: Satuan: | F3: 1 m'
A4: NO | B4: KOMPONEN | C4: SATUAN | D4: KOEFISIEN | E4: HARGA SATUAN (Rp) | F4: JUMLAH HARGA (Rp)
A5: A | B5: TENAGA KERJA
B6: Pekerja | C6: OH | D6: 0.15 | E6: 100000 | F6: =D6*E6 -> 15000
B7: Tukang listrik | C7: OH | D7: 0.15 | E7: 145000 | F7: =D7*E7 -> 21750
B8: Kepala tukang | C8: OH | D8: 0.1 | E8: 175000 | F8: =D8*E8 -> 17500
B9: Mandor | C9: OH | D9: 0.035 | E9: 200000 | F9: =D9*E9 -> 7000
B10: JUMLAH TENAGA KERJA | F10: =SUM(F6:F9) -> 61250
A11: B | B11: BAHAN
B12: Kabel NYY 4 x 16 mm² supreme | C12: m' | D12: 1.15 | E12: 267300 | F12: =D12*E12 -> 307395
B13: Skun 16 ml + sleeve | C13: buah | D13: 0.5 | E13: 7627 | F13: =D13*E13 -> 3813.5
B14: Nilon Cutter | C14: buah | D14: 0.05 | E14: 33750 | F14: =D14*E14 -> 1687.5
B15: skun 16ml | C15: buah | D15: 0.2 | E15: 5100 | F15: =D15*E15 -> 1020
B16: JUMLAH HARGA BAHAN | F16: =SUM(F12:F15) -> 313916
A17: C | B17: PERALATAN
B18: JUMLAH HARGA PERALATAN | F18: 0
A19: D | B19: JUMLAH HARGA TENAGA, BAHAN, DAN PERALATAN (A+B+C) | F19: =F10+F16+F18 -> 375166
A20: E | B20: OVERHEAD & PROFIT (10%) | F20: =ROUND(F19*10%, 2) -> 37516.6
A21: F | B21: HARGA SATUAN PEKERJAAN (D+E) | F21: =F19+F20 -> 412682.6
A24: Item | B24: Pemasangan 1 m' kabel NYM 2 x 2,5 mm² | E24: Satuan: | F24: 1 m'
A25: NO | B25: KOMPONEN | C25: SATUAN | D25: KOEFISIEN | E25: HARGA SATUAN (Rp) | F25: JUMLAH HARGA (Rp)
A26: A | B26: TENAGA KERJA
B27: Pekerja | C27: OH | D27: 0.024 | E27: 100000 | F27: =D27*E27 -> 2400
B28: Tukang listrik | C28: OH | D28: 0.04 | E28: 145000 | F28: =D28*E28 -> 5800
B29: Kepala tukang | C29: OH | D29: 0.004 | E29: 175000 | F29: =D29*E29 -> 700
B30: Mandor | C30: OH | D30: 0.002 | E30: 200000 | F30: =D30*E30 -> 400
B31: JUMLAH TENAGA KERJA | F31: =SUM(F27:F30) -> 9300
A32: B | B32: BAHAN
B33: Kabel NYM 2 x 2,5 mm² | C33: m' | D33: 1.2 | E33: 26326 | F33: =D33*E33 -> 31591.2
B34: JUMLAH HARGA BAHAN | F34: =SUM(F33:F33) -> 31591.2
A35: C | B35: PERALATAN
B36: JUMLAH HARGA PERALATAN | F36: 0
A37: D | B37: JUMLAH HARGA TENAGA, BAHAN, DAN PERALATAN (A+B+C) | F37: =F31+F34+F36 -> 40891.2
A38: E | B38: OVERHEAD & PROFIT (10%) | F38: =ROUND(F37*10%, 2) -> 4089.12
A39: F | B39: HARGA SATUAN PEKERJAAN (D+E) | F39: =F37+F38 -> 44980.32
A42: Item | B42: Pemasangan 1 m' kabel NYY 4 x 16 mm² | E42: Satuan: | F42: 1 m'
A43: NO | B43: KOMPONEN | C43: SATUAN | D43: KOEFISIEN | E43: HARGA SATUAN (Rp) | F43: JUMLAH HARGA (Rp)
A44: A | B44: TENAGA KERJA
B45: Pekerja | C45: OH | D45: 0.16666667 | E45: 100000 | F45: =D45*E45 -> 16666.667
...

Sheet Rekapitulasi RAB
A1: REKAPITULASI PENAWARAN HARGA (RAB)
A2: Proyek: ELEKTRIKAL PMI
A3: Kontraktor: Cv. Putra Sampean Dalem
A5: NO | B5: URAIAN PEKERJAAN | C5: VOL | D5: SAT | E5: HARGA SATUAN (RP) | F5: JUMLAH HARGA (RP)
A6: 1 | B6: Pemasangan 1 m' kabel NYY 4 x 16 mm² | C6: 20 | D6: m' | E6: ='AHSP 2026'!F21 -> 412682.6 | F6: =C6*E6 -> 8253652
A7: 2 | B7: Pemasangan 1 m' kabel NYM 2 x 2,5 mm² | C7: 5 | D7: m' | E7: ='AHSP 2026'!F39 -> 44980.32 | F7: =C7*E7 -> 224901.6
A8: 3 | B8: Pemasangan 1 m' kabel NYY 4 x 16 mm² | C8: 6 | D8: m' | E8: ='AHSP 2026'!F57 -> 432575 | F8: =C8*E8 -> 2595450
A9: 4 | B9: Pemasangan 1 buah Kabel Power Fire Alarm NYA 3x2x2,5 mm2 | C9: 10 | D9: m' | E9: ='AHSP 2026'!F75 -> 87023.75 | F9: =C9*E9 -> 870237.5
A10: 5 | B10: Pemasangan 1 Unit MCB Box | C10: 2 | D10: set | E10: ='AHSP 2026'!F105 -> 9007625 | F10: =C10*E10 -> 18015250
A11: 6 | B11: Pemasangan Downlight LED [Merk: HANNOCHS] (BASEMENT) | C11: 19 | D11: Buah | E11: ='AHSP 2026'!F122 -> 91560.522 | F11: =C11*E11 -> 1739649.9
A12: 7 | B12: Instalasi Stop Kontak [Merk: BROCO] + Uji Fungsi (LT 1 DAN LT 2) | C12: 3 | D12: Titik | E12: ='AHSP 2026'!F141 -> 161607.6 | F12: =C12*E12 -> 484822.8
B13: SUB TOTAL | F13: =SUM(F6:F12) -> 32183964
B14: PAJAK PERTAMBAHAN NILAI (PPN) 11% | F14: =ROUND(F13*11%, 2) -> 3540236
B15: GRAND TOTAL | F15: =F13+F14 -> 35724200
