Workbook

Sheet Cover
A1: RENCANA ANGGARAN BIAYA (RAB)
A2: PEKERJAAN PEMOTONGAN / PERAMPINGAN POHON
A3: Berdasarkan SE Ditjen Bina Konstruksi No. 47/SE/Dk/2026 (AHSP PUPR 2026)
A5: 📌 INFORMASI PROYEK & REGULASI | D5: 📊 RINGKASAN ESTIMASI BIAYA (SUMMARY)
A6: Nama Pekerjaan | B6: Pemeliharaan Pohon Jalan & Ruang Terbuka Hijau (RTH) | D6: Sub-Total Perampingan (Kelompok A) | F6: ='RAB Rekapitulasi'!G10
A7: Nomor Dokumen | B7: RAB-PPH-2026-001 | D7: Sub-Total Pemotongan (Kelompok B) | F7: ='RAB Rekapitulasi'!G18
A8: Tahun Anggaran | B8: 2026 | D8: Total Biaya Langsung Fisik | F8: ='RAB Rekapitulasi'!G19
A9: Tanggal RAB | B9: 22 July 2026 | D9: Biaya Penerapan SMKK (2.5%) | F9: ='RAB Rekapitulasi'!G20
A10: Satuan Biaya | B10: Rupiah (Rp) | D10: Jumlah Fisik + SMKK | F10: ='RAB Rekapitulasi'!G21
A11: Dasar Acuan | B11: SE Ditjen Bina Konstruksi No. 47/SE/Dk/2026 | D11: PPN (11%) | F11: ='RAB Rekapitulasi'!G22
A12: Biaya SMKK (K3) | B12: 2,5% dari Biaya Fisik (Permen PUPR 10/2021) | D12: GRAND TOTAL RAB | F12: ='RAB Rekapitulasi'!G23
A13: Pajak (PPN) | B13: 11% (UU HPP No. 7/2021)
A14: Overhead & Profit | B14: 15% dari Biaya Langsung
A15: Standar Ukur DBH | B15: DBH = 1,30 meter dari permukaan tanah
A18: Disetujui Oleh: | D18: Dibuat Oleh:
A19: Pejabat Pembuat Komitmen (PPK) | D19: Konsultan Perencana / Tim Teknik
A23: ( _______________________________ ) | D23: ( _______________________________ )

Sheet AHSP Detail
A1: ANALISIS HARGA SATUAN PEKERJAAN (AHSP) — PEMOTONGAN / PERAMPINGAN POHON
A2: Acuan: SE Ditjen BK No. 47/SE/Dk/2026 | Overhead & Profit 15% | Satuan per Batang Pohon
A3: No. | B3: Uraian Komponen / Pekerjaan | C3: Sat. | D3: Koefisien | E3: H. Satuan (Rp) | F3: Jumlah (Rp)
A4: KELOMPOK A — PERAMPINGAN / PEMANGKASAN POHON (Pohon Tetap Berdiri / Hidup)
A5: A.1 · Perampingan Ø 5–15 cm (Pohon Kecil / Perdu)
A6: A. TENAGA KERJA
B7: Pekerja Biasa | C7: OH | D7: 0.05 | E7: 120000 | F7: =D7*E7
B8: Tukang | C8: OH | D8: 0.08 | E8: 160000 | F8: =D8*E8
B9: Mandor | C9: OH | D9: 0.008 | E9: 185000 | F9: =D9*E9
B10: JUMLAH A. TENAGA KERJA | F10: =SUM(F7:F9)
A11: B. PERALATAN
B12: Chainsaw Kecil | C12: Jam | D12: 0.3 | E12: 45000 | F12: =D12*E12
B13: Alat Bantu | C13: LS | D13: 1 | E13: 750 | F13: =D13*E13
B14: JUMLAH B. PERALATAN | F14: =SUM(F12:F13)
A15: C. BAHAN / MATERIAL
B16: Cat Luka Pohon | C16: Kaleng | D16: 0.02 | E16: 95000 | F16: =D16*E16
B17: JUMLAH C. BAHAN / MATERIAL | F17: =SUM(F16:F16)
A18: D | B18: JUMLAH BIAYA LANGSUNG (A + B + C) | F18: =F10+F14+F17
A19: E | B19: OVERHEAD & PROFIT (15% x D) | F19: =F18*0.15
A20: F | B20: HARGA SATUAN PEKERJAAN (D + E) — per Batang | F20: =F18+F19
A22: A.2 · Perampingan Ø 15–30 cm (Pohon Sedang Kecil)
A23: A. TENAGA KERJA
B24: Pekerja Biasa | C24: OH | D24: 0.08 | E24: 120000 | F24: =D24*E24
B25: Tukang | C25: OH | D25: 0.12 | E25: 160000 | F25: =D25*E25
B26: Mandor | C26: OH | D26: 0.01 | E26: 185000 | F26: =D26*E26
B27: JUMLAH A. TENAGA KERJA | F27: =SUM(F24:F26)
A28: B. PERALATAN
B29: Chainsaw Kecil | C29: Jam | D29: 0.5 | E29: 45000 | F29: =D29*E29
B30: Alat Bantu | C30: LS | D30: 1 | E30: 1125 | F30: =D30*E30
B31: JUMLAH B. PERALATAN | F31: =SUM(F29:F30)
A32: C. BAHAN / MATERIAL
B33: Cat Luka Pohon | C33: Kaleng | D33: 0.05 | E33: 95000 | F33: =D33*E33
B34: JUMLAH C. BAHAN / MATERIAL | F34: =SUM(F33:F33)
A35: D | B35: JUMLAH BIAYA LANGSUNG (A + B + C) | F35: =F27+F31+F34
A36: E | B36: OVERHEAD & PROFIT (15% x D) | F36: =F35*0.15
A37: F | B37: HARGA SATUAN PEKERJAAN (D + E) — per Batang | F37: =F35+F36
A39: A.3 · Perampingan Ø 30–50 cm (Pohon Sedang)
A40: A. TENAGA KERJA
B41: Pekerja Biasa | C41: OH | D41: 0.15 | E41: 120000 | F41: =D41*E41
B42: Tukang | C42: OH | D42: 0.2 | E42: 160000 | F42: =D42*E42
...

Sheet RAB Rekapitulasi
A1: REKAPITULASI RENCANA ANGGARAN BIAYA (RAB)
A2: Pekerjaan Pemotongan / Perampingan Pohon | AHSP 2026 PUPR | SE Ditjen BK No. 47/SE/Dk/2026
A3: No. | B3: Kode | C3: Uraian Pekerjaan | D3: Satuan | E3: Volume (Batang) | F3: Harga Satuan (Rp) | G3: Jumlah Harga (Rp)
A4: A. PERAMPINGAN / PEMANGKASAN POHON (Pohon Tetap Berdiri / Hidup)
A5: 1 | B5: A.1 | C5: Perampingan Ø 5–15 cm — Pohon kecil / perdu | D5: Batang | E5: 3 | F5: 42000 | G5: =E5*F5
A6: 2 | B6: A.2 | C6: Perampingan Ø 15–30 cm — Pohon sedang kecil | D6: Batang | E6: 5 | F6: 68000 | G6: =E6*F6
A7: 3 | B7: A.3 | C7: Perampingan Ø 30–50 cm — Pohon sedang | D7: Batang | E7: 0 | F7: 133500 | G7: =E7*F7
A8: 4 | B8: A.4 | C8: Perampingan Ø 50–75 cm — Pohon besar | D8: Batang | E8: 0 | F8: 413000 | G8: =E8*F8
A9: 5 | B9: A.5 | C9: Perampingan Ø > 75 cm — Pohon sangat besar | D9: Batang | E9: 0 | F9: 841000 | G9: =E9*F9
A10: Sub-Total Kelompok A (Perampingan / Pemangkasan) | G10: =SUM(G5:G9)
A11: B. PEMOTONGAN / PENEBANGAN POHON (Ditebang Habis + Angkut Limbah)
A12: 1 | B12: B.1 | C12: Pemotongan Ø < 15 cm — Pohon kecil / perdu | D12: Batang | E12: 8 | F12: 36000 | G12: =E12*F12
A13: 2 | B13: B.2 | C13: Pemotongan Ø 15–30 cm — Pohon sedang kecil | D13: Batang | E13: 0 | F13: 64000 | G13: =E13*F13
A14: 3 | B14: B.3 | C14: Pemotongan Ø 30–50 cm — Pohon sedang | D14: Batang | E14: 3 | F14: 243000 | G14: =E14*F14
A15: 4 | B15: B.4 | C15: Pemotongan Ø 50–75 cm — Pohon besar | D15: Batang | E15: 2 | F15: 519500 | G15: =E15*F15
A16: 5 | B16: B.5 | C16: Pemotongan Ø 75–100 cm — Pohon sangat besar | D16: Batang | E16: 2 | F16: 927000 | G16: =E16*F16
A17: 6 | B17: B.6 | C17: Pemotongan Ø > 100 cm — Pohon raksasa | D17: Batang | E17: 1 | F17: 1492500 | G17: =E17*F17
A18: Sub-Total Kelompok B (Pemotongan / Penebangan) | G18: =SUM(G12:G17)
A19: JUMLAH BIAYA LANGSUNG FISIK (A + B) | G19: =G10+G18
A20: BIAYA PENERAPAN SMKK / K3 (2.5% x Total Fisik) | G20: =G19*0.025
A21: JUMLAH BIAYA FISIK + SMKK | G21: =G19+G20
A22: PAJAK PERTAMBAHAN NILAI (PPN 11%) | G22: =G21*0.11
A23: GRAND TOTAL RENCANA ANGGARAN BIAYA (RAB) | G23: =G21+G22
A25: 📌 CATATAN TEKNIS & SYARAT PELAKSANAAN
A26: 1. Regulasi Acuan: SE Ditjen Bina Konstruksi No. 47/SE/Dk/2026 (AHSP PUPR 2026).
A27: 2. Harga Satuan Dasar (HSD): Upah dan sewa alat mengacu pada acuan HSD standar. Wajib disesuaikan HSD Pemda setempat untuk tender resmi.
A28: 3. Penerapan SMKK (K3): Biaya K3 Konstruksi sebesar 2,5% diperhitungkan sesuai Permen PUPR No. 10/2021.
A29: 4. Pajak Pertambahan Nilai: PPN 11% dihitung dari Total Fisik + SMKK sesuai UU HPP No. 7/2021.
A30: 5. Komponen Angkut Limbah: Limbah kayu/ranting diangkut menggunakan armada Dump Truck (Angkut Limbah) untuk menjaga kebersihan lokasi kerja.
